Workbook

Sheet Original_Dataset
A1: Original Dataset (unmodified, as supplied)
A3: store_id | B3: month | C3: region | D3: store_type | E3: marketing_spend | F3: footfall | G3: avg_discount_pct | H3: staff_count | I3: inventory_availability_pct | J3: competitor_distance_km | K3: holiday_flag | L3: customer_rating | M3: monthly_sales | N3: monthly_profit
A4: STR-1001 | B4: 45658 | C4: East | D4: Residential | E4: 70389.11 | F4: 8302 | G4: 0.042 | H4: 17 | I4: 75 | J4: 5.28 | K4: 1 | L4: 3.1 | M4: 658832.62 | N4: 84349.93
A5: STR-1001 | B5: 45689 | C5: East | D5: Residential | E5: 43827.89 | F5: 8487 | G5: 0.168 | H5: 23 | I5: 84.4 | J5: 4.31 | K5: 0 | L5: 2.8 | M5: 634436 | N5: 106130.54
A6: STR-1001 | B6: 45717 | C6: East | D6: Residential | E6: 59921.75 | F6: 9113 | G6: 0.133 | H6: 20 | I6: 88 | J6: 12 | K6: 0 | L6: 3.2 | M6: 678722.06 | N6: 101883.86
A7: STR-1001 | B7: 45748 | C7: East | D7: Residential | E7: 56856.63 | F7: 9431 | G7: 0.142 | H7: 23 | I7: 86.9 | J7: 4.97 | K7: 0 | L7: 3.4 | M7: 658920.3 | N7: 97910.37
A8: STR-1002 | B8: 45658 | C8: East | D8: High Street | E8: 48412.64 | F8: 9545 | G8: 0.231 | H8: 21 | I8: 97.6 | J8: 6.94 | K8: 1 | L8: 4.2 | M8: 741341.44 | N8: 119208.17
A9: STR-1002 | B9: 45689 | C9: East | D9: High Street | E9: 64811.21 | F9: 9792 | G9: 0.112 | H9: 20 | I9: 84.2 | J9: 2.88 | K9: 0 | L9: 4.2 | M9: 761835.34 | N9: 149602.23
A10: STR-1002 | B10: 45717 | C10: East | D10: High Street | E10: 46213.45 | F10: 10616 | G10: 0.122 | H10: 22 | I10: 85.2 | J10: 0.2 | K10: 1 | L10: 4.1 | M10: 806615.54 | N10: 131364.62
A11: STR-1002 | B11: 45748 | C11: East | D11: High Street | E11: 68148.52 | F11: 8567 | G11: 0.127 | H11: 23 | I11: 95.6 | J11: 0.8 | K11: 0 | L11: 3.9 | M11: 850164.26 | N11: 149262.75
A12: STR-1003 | B12: 45658 | C12: North | D12: Airport | E12: 71838.86 | F12: 10979 | G12: 0.215 | H12: 26 | I12: 88.6 | J12: 7.7 | K12: 1 | L12: 3.8 | M12: 930581.7 | N12: 136207.98
A13: STR-1003 | B13: 45689 | C13: North | D13: Airport | E13: 68133.44 | F13: 9459 | G13: 0.22 | H13: 21 | I13: 85 | J13: 1.91 | K13: 0 | L13: 4.2 | M13: 779010.94 | N13: 106328.09
A14: STR-1003 | B14: 45717 | C14: North | D14: Airport | E14: 34285.21 | F14: 9172 | G14: 0.213 | H14: 22 | I14: 88.3 | J14: 10.46 | K14: 1 | L14: 3.8 | M14: 723060.76 | N14: 123131.24
A15: STR-1003 | B15: 45748 | C15: North | D15: Airport | E15: 67979.88 | F15: 11230 | G15: 0.002 | H15: 28 | I15: 85.3 | J15: 7.16 | K15: 0 | L15: 3.8 | M15: 910791.94 | N15: 158891.28
... A36: STR-1009 | B36: 45658 | C36: North | D36: Residential | E36: 54597.83 | F36: 9429 | G36: 0.188 | H36: 21 | I36: 83.3 | J36: 11.71 | K36: 0 | L36: 4.2 | M36: 641865.03 | N36: 81342.58
A37: STR-1009 | B37: 45689 | C37: North | D37: Residential | E37: 73771.91 | F37: 11695 | G37: 0.07 | H37: 25 | I37: 84.7 | J37: 0.62 | K37: 0 | M37: 799477.76 | N37: 164974.41
A38: STR-1009 | B38: 45717 | C38: North | D38: Residential | E38: 74413.88 | F38: 9449 | G38: 0.039 | H38: 23 | I38: 92.1 | J38: 2.12 | K38: 0 | L38: 3.5 | M38: 798952.17 | N38: 161499.04
A39: STR-1009 | B39: 45748 | C39: North | D39: Residential | E39: 52483.77 | F39: 10453 | G39: 0.247 | H39: 25 | I39: 99 | J39: 6.31 | K39: 0 | L39: 3.6 | M39: 800979.78 | N39: 149242.27
A40: STR-1010 | B40: 45658 | C40: North | D40: Mall | E40: 75269.87 | F40: 8838 | G40: 0.092 | H40: 21 | I40: 83.1 | J40: 9.56 | K40: 1 | L40: 4.2 | M40: 820593.93 | N40: 115860.06
A41: STR-1010 | B41: 45689 | C41: North | D41: Mall | E41: 61245.41 | F41: 8156 | G41: 0.156 | H41: 19 | I41: 92.9 | J41: 9.05 | K41: 0 | L41: 3.8 | M41: 718330.53 | N41: 93247.9
A42: STR-1010 | B42: 45717 | C42: North | D42: Mall | E42: 93381.26 | F42: 7562 | G42: 0.198 | H42: 19 | I42: 82.9 | J42: 5.05 | K42: 0 | L42: 4 | M42: 736633.4 | N42: 115654.66
A43: STR-1010 | B43: 45748 | C43: North | D43: Mall | E43: 65012.19 | F43: 9598 | G43: 0.085 | H43: 24 | I43: 98.3 | J43: 0.89 | K43: 0 | L43: 3.8 | M43: 828623.85 | N43: 167320.52
A44: STR-1011 | B44: 45658 | C44: East | D44: Mall | E44: 40462.94 | F44: 3660 | G44: 0.218 | H44: 11 | I44: 95.2 | J44: 5.57 | K44: 0 | L44: 4.4 | M44: 592195.85 | N44: 92291.56
A45: STR-1011 | B45: 45689 | C45: East | D45: Mall | E45: 46123.88 | F45: 3227 | G45: 0.143 | H45: 10 | I45: 75.4 | J45: 1.06 | K45: 0 | L45: 4.4 | M45: 532644.46 | N45: 60681.32
A46: STR-1011 | B46: 45717 | C46: East | D46: Mall | E46: 68077.54 | F46: 3360 | G46: 0.128 | H46: 14 | I46: 88.2 | J46: 1.24 | K46: 1 | L46: 4 | M46: 657429.18 | N46: 88919.74
A47: STR-1011 | B47: 45748 | C47: East | D47: Mall | E47: 64882.14 | F47: 3642 | G47: 0.019 | H47: 13 | I47: 87.8 | J47: 4.52 | K47: 0 | L47: 4.2 | M47: 605178 | N47: 106958.74
A48: STR-1012 | B48: 45658 | C48: West | D48: Residential | E48: 138855.51 | F48: 5145 | G48: 0.06 | H48: 17 | I48: 88.2 | J48: 9.58 | K48: 0 | L48: 3.2 | M48: 595467.6 | N48: 104276.46
A49: STR-1012 | B49: 45689 | C49: West | D49: Residential | E49: 63630.21 | F49: 4460 | G49: 0.235 | H49: 14 | I49: 98.6 | J49: 5.52 | K49: 0 | L49: 3.5 | M49: 599603.4 | N49: 112685.12
... A74: STR-1018 | B74: 45717 | C74: East | D74: High Street | E74: 60571.82 | F74: 3193 | G74: 0.197 | H74: 7 | I74: 99 | J74: 1.43 | K74: 0 | L74: 3.2 | M74: 605023.87 | N74: 98545.81
A75: STR-1018 | B75: 45748 | C75: East | D75: High Street | E75: 55081.16 | F75: 5485 | G75: 0.036 | H75: 12 | I75: 88 | K75: 0 | L75: 3.5 | M75: 674774.09 | N75: 141917.59
A76: STR-1019 | B76: 45658 | C76: East | D76: Residential | E76: 46201.46 | F76: 5918 | G76: 0.277 | H76: 13 | I76: 78.8 | J76: 4.91 | K76: 0 | L76: 4.5 | M76: 616069.41 | N76: 54453.99
A77: STR-1019 | B77: 45689 | C77: East | D77: Residential | E77: 53762.92 | F77: 6821 | G77: 0.066 | H77: 19 | I77: 94.6 | J77: 7.03 | K77: 0 | L77: 4.4 | M77: 630829.94 | N77: 117090.02
A78: STR-1019 | B78: 45717 | C78: East | D78: Residential | E78: 70144.78 | F78: 6806 | G78: 0.178 | H78: 20 | I78: 93.1 | J78: 0.28 | K78: 1 | L78: 4.3 | M78: 788087.68 | N78: 116803.42
A79: STR-1019 | B79: 45748 | C79: East | D79: Residential | E79: 58749.63 | F79: 8252 | G79: 0.203 | H79: 20 | I79: 85.2 | J79: 3.61 | K79: 0 | L79: 4.5 | M79: 680840.36 | N79: 68007.68
A80: STR-1020 | B80: 45658 | C80: South | D80: High Street | E80: 56973.18 | F80: 6662 | G80: 0.1 | H80: 15 | I80: 77.7 | J80: 7.52 | K80: 1 | L80: 3.2 | M80: 643657.47 | N80: 87022.45
A81: STR-1020 | B81: 45689 | C81: South | D81: High Street | E81: 54872.82 | F81: 5962 | G81: 0.064 | H81: 12 | I81: 85.4 | J81: 2.58 | K81: 0 | L81: 2.9 | M81: 691112.6 | N81: 109212.83
A82: STR-1020 | B82: 45717 | C82: South | D82: High Street | E82: 80562.81 | F82: 7470 | G82: 0.172 | H82: 16 | I82: 83.5 | J82: 2.29 | K82: 0 | L82: 3.3 | M82: 776922.17 | N82: 150701.93
A83: STR-1020 | B83: 45748 | C83: South | D83: High Street | E83: 77999.9 | F83: 5974 | G83: 0.252 | H83: 14 | I83: 81.3 | J83: 2.39 | K83: 0 | L83: 3.2 | M83: 636561.34 | N83: 93861.06
A84: STR-1021 | B84: 45658 | C84: West | D84: Mall | E84: 60881.01 | F84: 5410 | G84: 0.179 | H84: 15 | I84: 83.9 | J84: 5.24 | K84: 0 | L84: 4.6 | M84: 621369.58 | N84: 85493.64
A85: STR-1021 | B85: 45689 | C85: West | D85: Mall | E85: 60628.38 | F85: 4451 | G85: 0.095 | H85: 10 | I85: 89.6 | J85: 3.17 | K85: 0 | L85: 4.6 | M85: 682208.01 | N85: 110318.84
...

Sheet Cleaned_Prepared_Data
A1: Cleaned & Prepared Data
A2: Rows with missing competitor_distance_km or customer_rating removed (listwise deletion). monthly_profit retained for reference only — excluded from regression as it is an outcome of sales, not a driver. store_id and month retained as identifiers only.
P3: Original rows: | Q3: 320
A4: store_id | B4: month | C4: region | D4: store_type | E4: marketing_spend | F4: footfall | G4: avg_discount_pct | H4: staff_count | I4: inventory_availability_pct | J4: competitor_distance_km | K4: holiday_flag | L4: customer_rating | M4: monthly_sales | N4: monthly_profit | P4: Cleaned rows (used in models): | Q4: 306
A5: STR-1001 | B5: 45658 | C5: East | D5: Residential | E5: 70389.11 | F5: 8302 | G5: 0.042 | H5: 17 | I5: 75 | J5: 5.28 | K5: 1 | L5: 3.1 | M5: 658832.62 | N5: 84349.93 | P5: Rows dropped (missing data): | Q5: 14
A6: STR-1001 | B6: 45689 | C6: East | D6: Residential | E6: 43827.89 | F6: 8487 | G6: 0.168 | H6: 23 | I6: 84.4 | J6: 4.31 | K6: 0 | L6: 2.8 | M6: 634436 | N6: 106130.54
A7: STR-1001 | B7: 45717 | C7: East | D7: Residential | E7: 59921.75 | F7: 9113 | G7: 0.133 | H7: 20 | I7: 88 | J7: 12 | K7: 0 | L7: 3.2 | M7: 678722.06 | N7: 101883.86
A8: STR-1001 | B8: 45748 | C8: East | D8: Residential | E8: 56856.63 | F8: 9431 | G8: 0.142 | H8: 23 | I8: 86.9 | J8: 4.97 | K8: 0 | L8: 3.4 | M8: 658920.3 | N8: 97910.37
A9: STR-1002 | B9: 45658 | C9: East | D9: High Street | E9: 48412.64 | F9: 9545 | G9: 0.231 | H9: 21 | I9: 97.6 | J9: 6.94 | K9: 1 | L9: 4.2 | M9: 741341.44 | N9: 119208.17
A10: STR-1002 | B10: 45689 | C10: East | D10: High Street | E10: 64811.21 | F10: 9792 | G10: 0.112 | H10: 20 | I10: 84.2 | J10: 2.88 | K10: 0 | L10: 4.2 | M10: 761835.34 | N10: 149602.23
A11: STR-1002 | B11: 45717 | C11: East | D11: High Street | E11: 46213.45 | F11: 10616 | G11: 0.122 | H11: 22 | I11: 85.2 | J11: 0.2 | K11: 1 | L11: 4.1 | M11: 806615.54 | N11: 131364.62
A12: STR-1002 | B12: 45748 | C12: East | D12: High Street | E12: 68148.52 | F12: 8567 | G12: 0.127 | H12: 23 | I12: 95.6 | J12: 0.8 | K12: 0 | L12: 3.9 | M12: 850164.26 | N12: 149262.75
A13: STR-1003 | B13: 45658 | C13: North | D13: Airport | E13: 71838.86 | F13: 10979 | G13: 0.215 | H13: 26 | I13: 88.6 | J13: 7.7 | K13: 1 | L13: 3.8 | M13: 930581.7 | N13: 136207.98
A14: STR-1003 | B14: 45689 | C14: North | D14: Airport | E14: 68133.44 | F14: 9459 | G14: 0.22 | H14: 21 | I14: 85 | J14: 1.91 | K14: 0 | L14: 4.2 | M14: 779010.94 | N14: 106328.09
A15: STR-1003 | B15: 45717 | C15: North | D15: Airport | E15: 34285.21 | F15: 9172 | G15: 0.213 | H15: 22 | I15: 88.3 | J15: 10.46 | K15: 1 | L15: 3.8 | M15: 723060.76 | N15: 123131.24
A16: STR-1003 | B16: 45748 | C16: North | D16: Airport | E16: 67979.88 | F16: 11230 | G16: 0.002 | H16: 28 | I16: 85.3 | J16: 7.16 | K16: 0 | L16: 3.8 | M16: 910791.94 | N16: 158891.28
A17: STR-1004 | B17: 45658 | C17: East | D17: Residential | E17: 71828.26 | F17: 12775 | G17: 0.116 | H17: 30 | I17: 81.7 | J17: 4.24 | K17: 1 | L17: 4.2 | M17: 922168.6 | N17: 107494.53
... A310: STR-1080 | B310: 45748 | C310: East | D310: Residential | E310: 40553.11 | F310: 5317 | G310: 0.165 | H310: 17 | I310: 84.3 | J310: 11.82 | K310: 0 | L310: 4.1 | M310: 559660.84 | N310: 71443.61

Sheet Dummy_Variables
A1: Dummy Variable Creation — store_type
A2: Reference category = "High Street" (most frequent store type). Three dummy columns created: Airport, Mall, Residential. When all three = 0, the record is High Street. This avoids the dummy variable trap (perfect multicollinearity from including all 4 categories). | J2: Dummy variable check (counts):
J3: Airport = 1 count: | K3: =SUM(D5:D310) -> 28
A4: store_id | B4: month | C4: store_type | D4: is_Airport | E4: is_Mall | F4: is_Residential | G4: monthly_sales | J4: Mall = 1 count: | K4: =SUM(E5:E310) -> 74
A5: =Cleaned_Prepared_Data!A5 -> STR-1001 | B5: =Cleaned_Prepared_Data!B5 -> 45658 | C5: =Cleaned_Prepared_Data!D5 -> Residential | D5: =IF(C5="Airport",1,0) -> 0 | E5: =IF(C5="Mall",1,0) -> 0 | F5: =IF(C5="Residential",1,0) -> 1 | G5: =Cleaned_Prepared_Data!M5 -> 658832.62 | J5: Residential = 1 count: | K5: =SUM(F5:F310) -> 96
A6: =Cleaned_Prepared_Data!A6 -> STR-1001 | B6: =Cleaned_Prepared_Data!B6 -> 45689 | C6: =Cleaned_Prepared_Data!D6 -> Residential | D6: =IF(C6="Airport",1,0) -> 0 | E6: =IF(C6="Mall",1,0) -> 0 | F6: =IF(C6="Residential",1,0) -> 1 | G6: =Cleaned_Prepared_Data!M6 -> 634436 | J6: High Street (all=0) count: | K6: =COUNTIFS(D5:D310,0,E5:E310,0,F5:F310,0) -> 108
A7: =Cleaned_Prepared_Data!A7 -> STR-1001 | B7: =Cleaned_Prepared_Data!B7 -> 45717 | C7: =Cleaned_Prepared_Data!D7 -> Residential | D7: =IF(C7="Airport",1,0) -> 0 | E7: =IF(C7="Mall",1,0) -> 0 | F7: =IF(C7="Residential",1,0) -> 1 | G7: =Cleaned_Prepared_Data!M7 -> 678722.06 | J7: Total rows: | K7: =COUNTA(C5:C310) -> 306
A8: =Cleaned_Prepared_Data!A8 -> STR-1001 | B8: =Cleaned_Prepared_Data!B8 -> 45748 | C8: =Cleaned_Prepared_Data!D8 -> Residential | D8: =IF(C8="Airport",1,0) -> 0 | E8: =IF(C8="Mall",1,0) -> 0 | F8: =IF(C8="Residential",1,0) -> 1 | G8: =Cleaned_Prepared_Data!M8 -> 658920.3
A9: =Cleaned_Prepared_Data!A9 -> STR-1002 | B9: =Cleaned_Prepared_Data!B9 -> 45658 | C9: =Cleaned_Prepared_Data!D9 -> High Street | D9: =IF(C9="Airport",1,0) -> 0 | E9: =IF(C9="Mall",1,0) -> 0 | F9: =IF(C9="Residential",1,0) -> 0 | G9: =Cleaned_Prepared_Data!M9 -> 741341.44
A10: =Cleaned_Prepared_Data!A10 -> STR-1002 | B10: =Cleaned_Prepared_Data!B10 -> 45689 | C10: =Cleaned_Prepared_Data!D10 -> High Street | D10: =IF(C10="Airport",1,0) -> 0 | E10: =IF(C10="Mall",1,0) -> 0 | F10: =IF(C10="Residential",1,0) -> 0 | G10: =Cleaned_Prepared_Data!M10 -> 761835.34
A11: =Cleaned_Prepared_Data!A11 -> STR-1002 | B11: =Cleaned_Prepared_Data!B11 -> 45717 | C11: =Cleaned_Prepared_Data!D11 -> High Street | D11: =IF(C11="Airport",1,0) -> 0 | E11: =IF(C11="Mall",1,0) -> 0 | F11: =IF(C11="Residential",1,0) -> 0 | G11: =Cleaned_Prepared_Data!M11 -> 806615.54
A12: =Cleaned_Prepared_Data!A12 -> STR-1002 | B12: =Cleaned_Prepared_Data!B12 -> 45748 | C12: =Cleaned_Prepared_Data!D12 -> High Street | D12: =IF(C12="Airport",1,0) -> 0 | E12: =IF(C12="Mall",1,0) -> 0 | F12: =IF(C12="Residential",1,0) -> 0 | G12: =Cleaned_Prepared_Data!M12 -> 850164.26
A13: =Cleaned_Prepared_Data!A13 -> STR-1003 | B13: =Cleaned_Prepared_Data!B13 -> 45658 | C13: =Cleaned_Prepared_Data!D13 -> Airport | D13: =IF(C13="Airport",1,0) -> 1 | E13: =IF(C13="Mall",1,0) -> 0 | F13: =IF(C13="Residential",1,0) -> 0 | G13: =Cleaned_Prepared_Data!M13 -> 930581.7
A14: =Cleaned_Prepared_Data!A14 -> STR-1003 | B14: =Cleaned_Prepared_Data!B14 -> 45689 | C14: =Cleaned_Prepared_Data!D14 -> Airport | D14: =IF(C14="Airport",1,0) -> 1 | E14: =IF(C14="Mall",1,0) -> 0 | F14: =IF(C14="Residential",1,0) -> 0 | G14: =Cleaned_Prepared_Data!M14 -> 779010.94
A15: =Cleaned_Prepared_Data!A15 -> STR-1003 | B15: =Cleaned_Prepared_Data!B15 -> 45717 | C15: =Cleaned_Prepared_Data!D15 -> Airport | D15: =IF(C15="Airport",1,0) -> 1 | E15: =IF(C15="Mall",1,0) -> 0 | F15: =IF(C15="Residential",1,0) -> 0 | G15: =Cleaned_Prepared_Data!M15 -> 723060.76
A16: =Cleaned_Prepared_Data!A16 -> STR-1003 | B16: =Cleaned_Prepared_Data!B16 -> 45748 | C16: =Cleaned_Prepared_Data!D16 -> Airport | D16: =IF(C16="Airport",1,0) -> 1 | E16: =IF(C16="Mall",1,0) -> 0 | F16: =IF(C16="Residential",1,0) -> 0 | G16: =Cleaned_Prepared_Data!M16 -> 910791.94
A17: =Cleaned_Prepared_Data!A17 -> STR-1004 | B17: =Cleaned_Prepared_Data!B17 -> 45658 | C17: =Cleaned_Prepared_Data!D17 -> Residential | D17: =IF(C17="Airport",1,0) -> 0 | E17: =IF(C17="Mall",1,0) -> 0 | F17: =IF(C17="Residential",1,0) -> 1 | G17: =Cleaned_Prepared_Data!M17 -> 922168.6
A18: =Cleaned_Prepared_Data!A18 -> STR-1004 | B18: =Cleaned_Prepared_Data!B18 -> 45689 | C18: =Cleaned_Prepared_Data!D18 -> Residential | D18: =IF(C18="Airport",1,0) -> 0 | E18: =IF(C18="Mall",1,0) -> 0 | F18: =IF(C18="Residential",1,0) -> 1 | G18: =Cleaned_Prepared_Data!M18 -> 726606.28
A19: =Cleaned_Prepared_Data!A19 -> STR-1004 | B19: =Cleaned_Prepared_Data!B19 -> 45717 | C19: =Cleaned_Prepared_Data!D19 -> Residential | D19: =IF(C19="Airport",1,0) -> 0 | E19: =IF(C19="Mall",1,0) -> 0 | F19: =IF(C19="Residential",1,0) -> 1 | G19: =Cleaned_Prepared_Data!M19 -> 746501.09
... A310: =Cleaned_Prepared_Data!A310 -> STR-1080 | B310: =Cleaned_Prepared_Data!B310 -> 45748 | C310: =Cleaned_Prepared_Data!D310 -> Residential | D310: =IF(C310="Airport",1,0) -> 0 | E310: =IF(C310="Mall",1,0) -> 0 | F310: =IF(C310="Residential",1,0) -> 1 | G310: =Cleaned_Prepared_Data!M310 -> 559660.84

Sheet Simple_Regression
A1: Simple Linear Regression Models (monthly_sales as dependent variable)
A3: Model SR1 | B3: Independent variable: marketing_spend
A4: Slope (coefficient) | B4: =SLOPE(Cleaned_Prepared_Data!M5:M310,Cleaned_Prepared_Data!E5:E310) -> 2.0519316
A5: Intercept | B5: =INTERCEPT(Cleaned_Prepared_Data!M5:M310,Cleaned_Prepared_Data!E5:E310) -> 567463.56
A6: R-squared | B6: =RSQ(Cleaned_Prepared_Data!M5:M310,Cleaned_Prepared_Data!E5:E310) -> 0.15742646
A7: Correlation (r) | B7: =CORREL(Cleaned_Prepared_Data!M5:M310,Cleaned_Prepared_Data!E5:E310) -> 0.39677004
A8: Std Error (slope) | B8: =STEYX(Cleaned_Prepared_Data!M5:M310,Cleaned_Prepared_Data!E5:E310)/SQRT(DEVSQ(Cleaned_Prepared_Data!E5:E310)) -> 0.27226457
A9: t-stat (slope) | B9: =B4/B8 -> 7.5365355
A10: P-value (slope) | B10: =_xlfn.T.DIST.2T(ABS(B9),B11-2) -> 5.5808923e-13
A11: N (observations) | B11: =COUNT(Cleaned_Prepared_Data!E5:E310) -> 306
A12: =CONCATENATE("Equation: monthly_sales = ",TEXT(B5,"#,##0")," + ",TEXT(B4,"0.00")," * marketing_spend") -> Equation: monthly_sales = 567,464 + 2.05 * marketing_spend
A14: Model SR2 | B14: Independent variable: footfall
A15: Slope (coefficient) | B15: =SLOPE(Cleaned_Prepared_Data!M5:M310,Cleaned_Prepared_Data!F5:F310) -> 35.641531
A16: Intercept | B16: =INTERCEPT(Cleaned_Prepared_Data!M5:M310,Cleaned_Prepared_Data!F5:F310) -> 447699.03
A17: R-squared | B17: =RSQ(Cleaned_Prepared_Data!M5:M310,Cleaned_Prepared_Data!F5:F310) -> 0.73484317
A18: Correlation (r) | B18: =CORREL(Cleaned_Prepared_Data!M5:M310,Cleaned_Prepared_Data!F5:F310) -> 0.85722994
A19: Std Error (slope) | B19: =STEYX(Cleaned_Prepared_Data!M5:M310,Cleaned_Prepared_Data!F5:F310)/SQRT(DEVSQ(Cleaned_Prepared_Data!F5:F310)) -> 1.2279301
A20: t-stat (slope) | B20: =B15/B19 -> 29.025701
A21: P-value (slope) | B21: =_xlfn.T.DIST.2T(ABS(B20),B22-2) -> 1.2559351e-89
A22: N (observations) | B22: =COUNT(Cleaned_Prepared_Data!F5:F310) -> 306
A23: =CONCATENATE("Equation: monthly_sales = ",TEXT(B16,"#,##0")," + ",TEXT(B15,"0.00")," * footfall") -> Equation: monthly_sales = 447,699 + 35.64 * footfall
A25: Model SR3 | B25: Independent variable: avg_discount_pct
A26: Slope (coefficient) | B26: =SLOPE(Cleaned_Prepared_Data!M5:M310,Cleaned_Prepared_Data!G5:G310) -> -114707.66
A27: Intercept | B27: =INTERCEPT(Cleaned_Prepared_Data!M5:M310,Cleaned_Prepared_Data!G5:G310) -> 697538.04
A28: R-squared | B28: =RSQ(Cleaned_Prepared_Data!M5:M310,Cleaned_Prepared_Data!G5:G310) -> 0.0057430355
A29: Correlation (r) | B29: =CORREL(Cleaned_Prepared_Data!M5:M310,Cleaned_Prepared_Data!G5:G310) -> -0.075782818
A30: Std Error (slope) | B30: =STEYX(Cleaned_Prepared_Data!M5:M310,Cleaned_Prepared_Data!G5:G310)/SQRT(DEVSQ(Cleaned_Prepared_Data!G5:G310)) -> 86563.38
A31: t-stat (slope) | B31: =B26/B30 -> -1.3251292
A32: P-value (slope) | B32: =_xlfn.T.DIST.2T(ABS(B31),B33-2) -> 0.1861234
A33: N (observations) | B33: =COUNT(Cleaned_Prepared_Data!G5:G310) -> 306
A34: =CONCATENATE("Equation: monthly_sales = ",TEXT(B27,"#,##0")," + ",TEXT(B26,"#,##0")," * avg_discount_pct") -> Equation: monthly_sales = 697,538 + -114,708 * avg_discount_pct

Sheet Multiple_Regression
A1: Multiple Regression Model: monthly_sales ~ footfall + marketing_spend + inventory_availability_pct + staff_count + avg_discount_pct + store_type dummies
A2: Reference category for store_type: High Street (dummy columns: is_Airport, is_Mall, is_Residential)
K3: is_Residential | L3: is_Mall | M3: is_Airport | N3: avg_discount_pct | O3: staff_count | P3: inventory_availability_pct | Q3: marketing_spend | R3: footfall | S3: Intercept
A4: Readable Coefficient Summary
A5: Variable | B5: Coefficient | C5: Std Error | D5: t-stat | E5: P-value | J5: Coefficient | K5: {=LINEST(A41:A346,B41:I346,TRUE(),TRUE())} -> -15192.994 | L5: 11226.052 | M5: 21356.262 | N5: -57647.985 | O5: 2692.7752 | P5: 2856.8716 | Q5: 1.1495727 | R5: 28.785598 | S5: 138300.27
A6: Intercept | B6: =S5 -> 138300.27 | C6: =S6 -> 45504.23 | D6: =B6/C6 -> 3.0392838 | E6: =_xlfn.T.DIST.2T(ABS(D6),297) -> 0.0025824385 | J6: Std Error | K6: 6270.12 | L6: 6748.1249 | M6: 9488.1423 | N6: 37749.994 | O6: 1305.6223 | P6: 485.13864 | Q6: 0.13143198 | R6: 2.5653694 | S6: 45504.23
A7: footfall | B7: =R5 -> 28.785598 | C7: =R6 -> 2.5653694 | D7: =B7/C7 -> 11.22084 | E7: =_xlfn.T.DIST.2T(ABS(D7),297) -> 1.3547651e-24 | J7: R² / SE_y | K7: 0.8185268 | L7: 44433.921 | M7: #N/A | N7: #N/A | O7: #N/A | P7: #N/A | Q7: #N/A | R7: #N/A | S7: #N/A
A8: marketing_spend | B8: =Q5 -> 1.1495727 | C8: =Q6 -> 0.13143198 | D8: =B8/C8 -> 8.7465219 | E8: =_xlfn.T.DIST.2T(ABS(D8),297) -> 1.6708318e-16 | J8: F-stat / df | K8: 167.45066 | L8: 297 | M8: #N/A | N8: #N/A | O8: #N/A | P8: #N/A | Q8: #N/A | R8: #N/A | S8: #N/A
A9: inventory_availability_pct | B9: =P5 -> 2856.8716 | C9: =P6 -> 485.13864 | D9: =B9/C9 -> 5.8887736 | E9: =_xlfn.T.DIST.2T(ABS(D9),297) -> 1.0515865e-08 | J9: SS_reg / SS_resid | K9: 2.644881e+12 | L9: 5.8638889e+11 | M9: #N/A | N9: #N/A | O9: #N/A | P9: #N/A | Q9: #N/A | R9: #N/A | S9: #N/A
A10: staff_count | B10: =O5 -> 2692.7752 | C10: =O6 -> 1305.6223 | D10: =B10/C10 -> 2.0624458 | E10: =_xlfn.T.DIST.2T(ABS(D10),297) -> 0.040034692
A11: avg_discount_pct | B11: =N5 -> -57647.985 | C11: =N6 -> 37749.994 | D11: =B11/C11 -> -1.5270992 | E11: =_xlfn.T.DIST.2T(ABS(D11),297) -> 0.12780058
A12: is_Airport | B12: =M5 -> 21356.262 | C12: =M6 -> 9488.1423 | D12: =B12/C12 -> 2.250837 | E12: =_xlfn.T.DIST.2T(ABS(D12),297) -> 0.025127124
A13: is_Mall | B13: =L5 -> 11226.052 | C13: =L6 -> 6748.1249 | D13: =B13/C13 -> 1.6635809 | E13: =_xlfn.T.DIST.2T(ABS(D13),297) -> 0.097250961
A14: is_Residential | B14: =K5 -> -15192.994 | C14: =K6 -> 6270.12 | D14: =B14/C14 -> -2.4230786 | E14: =_xlfn.T.DIST.2T(ABS(D14),297) -> 0.015987342
A16: R-squared: | B16: =K7 -> 0.8185268
A17: F-statistic: | B17: =K8 -> 167.45066
A18: Residual df: | B18: =L8 -> 297
A19: N (observations): | B19: 306
A21: Note: data staging block for LINEST is located in rows 40+ below (hidden helper area).
A26: Note: hidden columns M:S contain unused LINEST stats-array cells; #N/A there is standard Excel behavior, not a calculation error.
A40: monthly_sales | B40: footfall | C40: marketing_spend | D40: inventory_availability_pct | E40: staff_count | F40: avg_discount_pct | G40: is_Airport | H40: is_Mall | I40: is_Residential
A41: =Cleaned_Prepared_Data!M5 -> 658832.62 | B41: =Cleaned_Prepared_Data!F5 -> 8302 | C41: =Cleaned_Prepared_Data!E5 -> 70389.11 | D41: =Cleaned_Prepared_Data!I5 -> 75 | E41: =Cleaned_Prepared_Data!H5 -> 17 | F41: =Cleaned_Prepared_Data!G5 -> 0.042 | G41: =Dummy_Variables!D5 -> 0 | H41: =Dummy_Variables!E5 -> 0 | I41: =Dummy_Variables!F5 -> 1
A42: =Cleaned_Prepared_Data!M6 -> 634436 | B42: =Cleaned_Prepared_Data!F6 -> 8487 | C42: =Cleaned_Prepared_Data!E6 -> 43827.89 | D42: =Cleaned_Prepared_Data!I6 -> 84.4 | E42: =Cleaned_Prepared_Data!H6 -> 23 | F42: =Cleaned_Prepared_Data!G6 -> 0.168 | G42: =Dummy_Variables!D6 -> 0 | H42: =Dummy_Variables!E6 -> 0 | I42: =Dummy_Variables!F6 -> 1
A43: =Cleaned_Prepared_Data!M7 -> 678722.06 | B43: =Cleaned_Prepared_Data!F7 -> 9113 | C43: =Cleaned_Prepared_Data!E7 -> 59921.75 | D43: =Cleaned_Prepared_Data!I7 -> 88 | E43: =Cleaned_Prepared_Data!H7 -> 20 | F43: =Cleaned_Prepared_Data!G7 -> 0.133 | G43: =Dummy_Variables!D7 -> 0 | H43: =Dummy_Variables!E7 -> 0 | I43: =Dummy_Variables!F7 -> 1
A44: =Cleaned_Prepared_Data!M8 -> 658920.3 | B44: =Cleaned_Prepared_Data!F8 -> 9431 | C44: =Cleaned_Prepared_Data!E8 -> 56856.63 | D44: =Cleaned_Prepared_Data!I8 -> 86.9 | E44: =Cleaned_Prepared_Data!H8 -> 23 | F44: =Cleaned_Prepared_Data!G8 -> 0.142 | G44: =Dummy_Variables!D8 -> 0 | H44: =Dummy_Variables!E8 -> 0 | I44: =Dummy_Variables!F8 -> 1
A45: =Cleaned_Prepared_Data!M9 -> 741341.44 | B45: =Cleaned_Prepared_Data!F9 -> 9545 | C45: =Cleaned_Prepared_Data!E9 -> 48412.64 | D45: =Cleaned_Prepared_Data!I9 -> 97.6 | E45: =Cleaned_Prepared_Data!H9 -> 21 | F45: =Cleaned_Prepared_Data!G9 -> 0.231 | G45: =Dummy_Variables!D9 -> 0 | H45: =Dummy_Variables!E9 -> 0 | I45: =Dummy_Variables!F9 -> 0
A46: =Cleaned_Prepared_Data!M10 -> 761835.34 | B46: =Cleaned_Prepared_Data!F10 -> 9792 | C46: =Cleaned_Prepared_Data!E10 -> 64811.21 | D46: =Cleaned_Prepared_Data!I10 -> 84.2 | E46: =Cleaned_Prepared_Data!H10 -> 20 | F46: =Cleaned_Prepared_Data!G10 -> 0.112 | G46: =Dummy_Variables!D10 -> 0 | H46: =Dummy_Variables!E10 -> 0 | I46: =Dummy_Variables!F10 -> 0
A47: =Cleaned_Prepared_Data!M11 -> 806615.54 | B47: =Cleaned_Prepared_Data!F11 -> 10616 | C47: =Cleaned_Prepared_Data!E11 -> 46213.45 | D47: =Cleaned_Prepared_Data!I11 -> 85.2 | E47: =Cleaned_Prepared_Data!H11 -> 22 | F47: =Cleaned_Prepared_Data!G11 -> 0.122 | G47: =Dummy_Variables!D11 -> 0 | H47: =Dummy_Variables!E11 -> 0 | I47: =Dummy_Variables!F11 -> 0
A48: =Cleaned_Prepared_Data!M12 -> 850164.26 | B48: =Cleaned_Prepared_Data!F12 -> 8567 | C48: =Cleaned_Prepared_Data!E12 -> 68148.52 | D48: =Cleaned_Prepared_Data!I12 -> 95.6 | E48: =Cleaned_Prepared_Data!H12 -> 23 | F48: =Cleaned_Prepared_Data!G12 -> 0.127 | G48: =Dummy_Variables!D12 -> 0 | H48: =Dummy_Variables!E12 -> 0 | I48: =Dummy_Variables!F12 -> 0
A49: =Cleaned_Prepared_Data!M13 -> 930581.7 | B49: =Cleaned_Prepared_Data!F13 -> 10979 | C49: =Cleaned_Prepared_Data!E13 -> 71838.86 | D49: =Cleaned_Prepared_Data!I13 -> 88.6 | E49: =Cleaned_Prepared_Data!H13 -> 26 | F49: =Cleaned_Prepared_Data!G13 -> 0.215 | G49: =Dummy_Variables!D13 -> 1 | H49: =Dummy_Variables!E13 -> 0 | I49: =Dummy_Variables!F13 -> 0
A50: =Cleaned_Prepared_Data!M14 -> 779010.94 | B50: =Cleaned_Prepared_Data!F14 -> 9459 | C50: =Cleaned_Prepared_Data!E14 -> 68133.44 | D50: =Cleaned_Prepared_Data!I14 -> 85 | E50: =Cleaned_Prepared_Data!H14 -> 21 | F50: =Cleaned_Prepared_Data!G14 -> 0.22 | G50: =Dummy_Variables!D14 -> 1 | H50: =Dummy_Variables!E14 -> 0 | I50: =Dummy_Variables!F14 -> 0
A51: =Cleaned_Prepared_Data!M15 -> 723060.76 | B51: =Cleaned_Prepared_Data!F15 -> 9172 | C51: =Cleaned_Prepared_Data!E15 -> 34285.21 | D51: =Cleaned_Prepared_Data!I15 -> 88.3 | E51: =Cleaned_Prepared_Data!H15 -> 22 | F51: =Cleaned_Prepared_Data!G15 -> 0.213 | G51: =Dummy_Variables!D15 -> 1 | H51: =Dummy_Variables!E15 -> 0 | I51: =Dummy_Variables!F15 -> 0
A52: =Cleaned_Prepared_Data!M16 -> 910791.94 | B52: =Cleaned_Prepared_Data!F16 -> 11230 | C52: =Cleaned_Prepared_Data!E16 -> 67979.88 | D52: =Cleaned_Prepared_Data!I16 -> 85.3 | E52: =Cleaned_Prepared_Data!H16 -> 28 | F52: =Cleaned_Prepared_Data!G16 -> 0.002 | G52: =Dummy_Variables!D16 -> 1 | H52: =Dummy_Variables!E16 -> 0 | I52: =Dummy_Variables!F16 -> 0
... A346: =Cleaned_Prepared_Data!M310 -> 559660.84 | B346: =Cleaned_Prepared_Data!F310 -> 5317 | C346: =Cleaned_Prepared_Data!E310 -> 40553.11 | D346: =Cleaned_Prepared_Data!I310 -> 84.3 | E346: =Cleaned_Prepared_Data!H310 -> 17 | F346: =Cleaned_Prepared_Data!G310 -> 0.165 | G346: =Dummy_Variables!D310 -> 0 | H346: =Dummy_Variables!E310 -> 0 | I346: =Dummy_Variables!F310 -> 1

Sheet Prediction_Residuals
A1: Predicted Sales & Residuals — Final Multiple Regression Model
A2: Predicted = Intercept + (footfall coef × footfall) + (marketing_spend coef × marketing_spend) + (inventory coef × inventory) + (staff coef × staff_count) + (discount coef × discount) + (Airport coef × is_Airport) + (Mall coef × is_Mall) + (Residential coef × is_Residential). Residual = Actual − Predicted.
A4: store_id | B4: month | C4: region | D4: store_type | E4: monthly_sales (actual) | F4: predicted_sales | G4: residual | J4: Top 5 Largest POSITIVE Residuals (model under-predicts)
A5: =Cleaned_Prepared_Data!A5 -> STR-1001 | B5: =Cleaned_Prepared_Data!B5 -> 45658 | C5: =Cleaned_Prepared_Data!C5 -> East | D5: =Cleaned_Prepared_Data!D5 -> Residential | E5: =Cleaned_Prepared_Data!M5 -> 658832.62 | F5: =Multiple_Regression!$B$6+Multiple_Regression!$B$7*Cleaned_Prepared_Data!F5+Multiple_Regression!$B$8*Cleaned_Prepared_Data!E5+Multiple_Regression!$B$9*Cleaned_Prepared_Data!I5+Multiple_Regression!$B$10*Cleaned_Prepared_Data!H5+Multiple_Regression!$B$11*Cleaned_Prepared_Data!G5+Multiple_Regression!$B$12*Dummy_Variables!D5+Multiple_Regression!$B$13*Dummy_Variables!E5+Multiple_Regression!$B$14*Dummy_Variables!F5 -> 700624.05 | G5: =E5-F5 -> -41791.425 | J5: store_id | K5: store_type | L5: residual | M5: predicted_sales
A6: =Cleaned_Prepared_Data!A6 -> STR-1001 | B6: =Cleaned_Prepared_Data!B6 -> 45689 | C6: =Cleaned_Prepared_Data!C6 -> East | D6: =Cleaned_Prepared_Data!D6 -> Residential | E6: =Cleaned_Prepared_Data!M6 -> 634436 | F6: =Multiple_Regression!$B$6+Multiple_Regression!$B$7*Cleaned_Prepared_Data!F6+Multiple_Regression!$B$8*Cleaned_Prepared_Data!E6+Multiple_Regression!$B$9*Cleaned_Prepared_Data!I6+Multiple_Regression!$B$10*Cleaned_Prepared_Data!H6+Multiple_Regression!$B$11*Cleaned_Prepared_Data!G6+Multiple_Regression!$B$12*Dummy_Variables!D6+Multiple_Regression!$B$13*Dummy_Variables!E6+Multiple_Regression!$B$14*Dummy_Variables!F6 -> 711162.93 | G6: =E6-F6 -> -76726.927 | J6: =INDEX($A$5:$A$310,MATCH(LARGE($G$5:$G$310,1),$G$5:$G$310,0)) -> STR-1030 | K6: =INDEX($D$5:$D$310,MATCH(LARGE($G$5:$G$310,1),$G$5:$G$310,0)) -> Residential | L6: =LARGE($G$5:$G$310,1) -> 105973.74 | M6: =INDEX($F$5:$F$310,MATCH(LARGE($G$5:$G$310,1),$G$5:$G$310,0)) -> 714545.3
A7: =Cleaned_Prepared_Data!A7 -> STR-1001 | B7: =Cleaned_Prepared_Data!B7 -> 45717 | C7: =Cleaned_Prepared_Data!C7 -> East | D7: =Cleaned_Prepared_Data!D7 -> Residential | E7: =Cleaned_Prepared_Data!M7 -> 678722.06 | F7: =Multiple_Regression!$B$6+Multiple_Regression!$B$7*Cleaned_Prepared_Data!F7+Multiple_Regression!$B$8*Cleaned_Prepared_Data!E7+Multiple_Regression!$B$9*Cleaned_Prepared_Data!I7+Multiple_Regression!$B$10*Cleaned_Prepared_Data!H7+Multiple_Regression!$B$11*Cleaned_Prepared_Data!G7+Multiple_Regression!$B$12*Dummy_Variables!D7+Multiple_Regression!$B$13*Dummy_Variables!E7+Multiple_Regression!$B$14*Dummy_Variables!F7 -> 751907.86 | G7: =E7-F7 -> -73185.804 | J7: =INDEX($A$5:$A$310,MATCH(LARGE($G$5:$G$310,2),$G$5:$G$310,0)) -> STR-1028 | K7: =INDEX($D$5:$D$310,MATCH(LARGE($G$5:$G$310,2),$G$5:$G$310,0)) -> Mall | L7: =LARGE($G$5:$G$310,2) -> 95477.29 | M7: =INDEX($F$5:$F$310,MATCH(LARGE($G$5:$G$310,2),$G$5:$G$310,0)) -> 618133.87
A8: =Cleaned_Prepared_Data!A8 -> STR-1001 | B8: =Cleaned_Prepared_Data!B8 -> 45748 | C8: =Cleaned_Prepared_Data!C8 -> East | D8: =Cleaned_Prepared_Data!D8 -> Residential | E8: =Cleaned_Prepared_Data!M8 -> 658920.3 | F8: =Multiple_Regression!$B$6+Multiple_Regression!$B$7*Cleaned_Prepared_Data!F8+Multiple_Regression!$B$8*Cleaned_Prepared_Data!E8+Multiple_Regression!$B$9*Cleaned_Prepared_Data!I8+Multiple_Regression!$B$10*Cleaned_Prepared_Data!H8+Multiple_Regression!$B$11*Cleaned_Prepared_Data!G8+Multiple_Regression!$B$12*Dummy_Variables!D8+Multiple_Regression!$B$13*Dummy_Variables!E8+Multiple_Regression!$B$14*Dummy_Variables!F8 -> 761955.04 | G8: =E8-F8 -> -103034.74 | J8: =INDEX($A$5:$A$310,MATCH(LARGE($G$5:$G$310,3),$G$5:$G$310,0)) -> STR-1032 | K8: =INDEX($D$5:$D$310,MATCH(LARGE($G$5:$G$310,3),$G$5:$G$310,0)) -> High Street | L8: =LARGE($G$5:$G$310,3) -> 94323.66 | M8: =INDEX($F$5:$F$310,MATCH(LARGE($G$5:$G$310,3),$G$5:$G$310,0)) -> 820220.51
A9: =Cleaned_Prepared_Data!A9 -> STR-1002 | B9: =Cleaned_Prepared_Data!B9 -> 45658 | C9: =Cleaned_Prepared_Data!C9 -> East | D9: =Cleaned_Prepared_Data!D9 -> High Street | E9: =Cleaned_Prepared_Data!M9 -> 741341.44 | F9: =Multiple_Regression!$B$6+Multiple_Regression!$B$7*Cleaned_Prepared_Data!F9+Multiple_Regression!$B$8*Cleaned_Prepared_Data!E9+Multiple_Regression!$B$9*Cleaned_Prepared_Data!I9+Multiple_Regression!$B$10*Cleaned_Prepared_Data!H9+Multiple_Regression!$B$11*Cleaned_Prepared_Data!G9+Multiple_Regression!$B$12*Dummy_Variables!D9+Multiple_Regression!$B$13*Dummy_Variables!E9+Multiple_Regression!$B$14*Dummy_Variables!F9 -> 790774.92 | G9: =E9-F9 -> -49433.478 | J9: =INDEX($A$5:$A$310,MATCH(LARGE($G$5:$G$310,4),$G$5:$G$310,0)) -> STR-1073 | K9: =INDEX($D$5:$D$310,MATCH(LARGE($G$5:$G$310,4),$G$5:$G$310,0)) -> Residential | L9: =LARGE($G$5:$G$310,4) -> 93670.056 | M9: =INDEX($F$5:$F$310,MATCH(LARGE($G$5:$G$310,4),$G$5:$G$310,0)) -> 719646.65
A10: =Cleaned_Prepared_Data!A10 -> STR-1002 | B10: =Cleaned_Prepared_Data!B10 -> 45689 | C10: =Cleaned_Prepared_Data!C10 -> East | D10: =Cleaned_Prepared_Data!D10 -> High Street | E10: =Cleaned_Prepared_Data!M10 -> 761835.34 | F10: =Multiple_Regression!$B$6+Multiple_Regression!$B$7*Cleaned_Prepared_Data!F10+Multiple_Regression!$B$8*Cleaned_Prepared_Data!E10+Multiple_Regression!$B$9*Cleaned_Prepared_Data!I10+Multiple_Regression!$B$10*Cleaned_Prepared_Data!H10+Multiple_Regression!$B$11*Cleaned_Prepared_Data!G10+Multiple_Regression!$B$12*Dummy_Variables!D10+Multiple_Regression!$B$13*Dummy_Variables!E10+Multiple_Regression!$B$14*Dummy_Variables!F10 -> 782621.56 | G10: =E10-F10 -> -20786.224 | J10: =INDEX($A$5:$A$310,MATCH(LARGE($G$5:$G$310,5),$G$5:$G$310,0)) -> STR-1026 | K10: =INDEX($D$5:$D$310,MATCH(LARGE($G$5:$G$310,5),$G$5:$G$310,0)) -> Mall | L10: =LARGE($G$5:$G$310,5) -> 92050.971 | M10: =INDEX($F$5:$F$310,MATCH(LARGE($G$5:$G$310,5),$G$5:$G$310,0)) -> 533463.07
A11: =Cleaned_Prepared_Data!A11 -> STR-1002 | B11: =Cleaned_Prepared_Data!B11 -> 45717 | C11: =Cleaned_Prepared_Data!C11 -> East | D11: =Cleaned_Prepared_Data!D11 -> High Street | E11: =Cleaned_Prepared_Data!M11 -> 806615.54 | F11: =Multiple_Regression!$B$6+Multiple_Regression!$B$7*Cleaned_Prepared_Data!F11+Multiple_Regression!$B$8*Cleaned_Prepared_Data!E11+Multiple_Regression!$B$9*Cleaned_Prepared_Data!I11+Multiple_Regression!$B$10*Cleaned_Prepared_Data!H11+Multiple_Regression!$B$11*Cleaned_Prepared_Data!G11+Multiple_Regression!$B$12*Dummy_Variables!D11+Multiple_Regression!$B$13*Dummy_Variables!E11+Multiple_Regression!$B$14*Dummy_Variables!F11 -> 792627.36 | G11: =E11-F11 -> 13988.178
A12: =Cleaned_Prepared_Data!A12 -> STR-1002 | B12: =Cleaned_Prepared_Data!B12 -> 45748 | C12: =Cleaned_Prepared_Data!C12 -> East | D12: =Cleaned_Prepared_Data!D12 -> High Street | E12: =Cleaned_Prepared_Data!M12 -> 850164.26 | F12: =Multiple_Regression!$B$6+Multiple_Regression!$B$7*Cleaned_Prepared_Data!F12+Multiple_Regression!$B$8*Cleaned_Prepared_Data!E12+Multiple_Regression!$B$9*Cleaned_Prepared_Data!I12+Multiple_Regression!$B$10*Cleaned_Prepared_Data!H12+Multiple_Regression!$B$11*Cleaned_Prepared_Data!G12+Multiple_Regression!$B$12*Dummy_Variables!D12+Multiple_Regression!$B$13*Dummy_Variables!E12+Multiple_Regression!$B$14*Dummy_Variables!F12 -> 790977.63 | G12: =E12-F12 -> 59186.631 | J12: Top 5 Largest NEGATIVE Residuals (model over-predicts)
A13: =Cleaned_Prepared_Data!A13 -> STR-1003 | B13: =Cleaned_Prepared_Data!B13 -> 45658 | C13: =Cleaned_Prepared_Data!C13 -> North | D13: =Cleaned_Prepared_Data!D13 -> Airport | E13: =Cleaned_Prepared_Data!M13 -> 930581.7 | F13: =Multiple_Regression!$B$6+Multiple_Regression!$B$7*Cleaned_Prepared_Data!F13+Multiple_Regression!$B$8*Cleaned_Prepared_Data!E13+Multiple_Regression!$B$9*Cleaned_Prepared_Data!I13+Multiple_Regression!$B$10*Cleaned_Prepared_Data!H13+Multiple_Regression!$B$11*Cleaned_Prepared_Data!G13+Multiple_Regression!$B$12*Dummy_Variables!D13+Multiple_Regression!$B$13*Dummy_Variables!E13+Multiple_Regression!$B$14*Dummy_Variables!F13 -> 869014.27 | G13: =E13-F13 -> 61567.431 | J13: store_id | K13: store_type | L13: residual | M13: predicted_sales
A14: =Cleaned_Prepared_Data!A14 -> STR-1003 | B14: =Cleaned_Prepared_Data!B14 -> 45689 | C14: =Cleaned_Prepared_Data!C14 -> North | D14: =Cleaned_Prepared_Data!D14 -> Airport | E14: =Cleaned_Prepared_Data!M14 -> 779010.94 | F14: =Multiple_Regression!$B$6+Multiple_Regression!$B$7*Cleaned_Prepared_Data!F14+Multiple_Regression!$B$8*Cleaned_Prepared_Data!E14+Multiple_Regression!$B$9*Cleaned_Prepared_Data!I14+Multiple_Regression!$B$10*Cleaned_Prepared_Data!H14+Multiple_Regression!$B$11*Cleaned_Prepared_Data!G14+Multiple_Regression!$B$12*Dummy_Variables!D14+Multiple_Regression!$B$13*Dummy_Variables!E14+Multiple_Regression!$B$14*Dummy_Variables!F14 -> 796963.66 | G14: =E14-F14 -> -17952.716 | J14: =INDEX($A$5:$A$310,MATCH(SMALL($G$5:$G$310,1),$G$5:$G$310,0)) -> STR-1017 | K14: =INDEX($D$5:$D$310,MATCH(SMALL($G$5:$G$310,1),$G$5:$G$310,0)) -> High Street | L14: =SMALL($G$5:$G$310,1) -> -152088.74 | M14: =INDEX($F$5:$F$310,MATCH(SMALL($G$5:$G$310,1),$G$5:$G$310,0)) -> 837467.82
A15: =Cleaned_Prepared_Data!A15 -> STR-1003 | B15: =Cleaned_Prepared_Data!B15 -> 45717 | C15: =Cleaned_Prepared_Data!C15 -> North | D15: =Cleaned_Prepared_Data!D15 -> Airport | E15: =Cleaned_Prepared_Data!M15 -> 723060.76 | F15: =Multiple_Regression!$B$6+Multiple_Regression!$B$7*Cleaned_Prepared_Data!F15+Multiple_Regression!$B$8*Cleaned_Prepared_Data!E15+Multiple_Regression!$B$9*Cleaned_Prepared_Data!I15+Multiple_Regression!$B$10*Cleaned_Prepared_Data!H15+Multiple_Regression!$B$11*Cleaned_Prepared_Data!G15+Multiple_Regression!$B$12*Dummy_Variables!D15+Multiple_Regression!$B$13*Dummy_Variables!E15+Multiple_Regression!$B$14*Dummy_Variables!F15 -> 762315.18 | G15: =E15-F15 -> -39254.417 | J15: =INDEX($A$5:$A$310,MATCH(SMALL($G$5:$G$310,2),$G$5:$G$310,0)) -> STR-1012 | K15: =INDEX($D$5:$D$310,MATCH(SMALL($G$5:$G$310,2),$G$5:$G$310,0)) -> Residential | L15: =SMALL($G$5:$G$310,2) -> -129660.46 | M15: =INDEX($F$5:$F$310,MATCH(SMALL($G$5:$G$310,2),$G$5:$G$310,0)) -> 725128.06
A16: =Cleaned_Prepared_Data!A16 -> STR-1003 | B16: =Cleaned_Prepared_Data!B16 -> 45748 | C16: =Cleaned_Prepared_Data!C16 -> North | D16: =Cleaned_Prepared_Data!D16 -> Airport | E16: =Cleaned_Prepared_Data!M16 -> 910791.94 | F16: =Multiple_Regression!$B$6+Multiple_Regression!$B$7*Cleaned_Prepared_Data!F16+Multiple_Regression!$B$8*Cleaned_Prepared_Data!E16+Multiple_Regression!$B$9*Cleaned_Prepared_Data!I16+Multiple_Regression!$B$10*Cleaned_Prepared_Data!H16+Multiple_Regression!$B$11*Cleaned_Prepared_Data!G16+Multiple_Regression!$B$12*Dummy_Variables!D16+Multiple_Regression!$B$13*Dummy_Variables!E16+Multiple_Regression!$B$14*Dummy_Variables!F16 -> 880040.17 | G16: =E16-F16 -> 30751.769 | J16: =INDEX($A$5:$A$310,MATCH(SMALL($G$5:$G$310,3),$G$5:$G$310,0)) -> STR-1023 | K16: =INDEX($D$5:$D$310,MATCH(SMALL($G$5:$G$310,3),$G$5:$G$310,0)) -> Mall | L16: =SMALL($G$5:$G$310,3) -> -120619.21 | M16: =INDEX($F$5:$F$310,MATCH(SMALL($G$5:$G$310,3),$G$5:$G$310,0)) -> 747791.11
A17: =Cleaned_Prepared_Data!A17 -> STR-1004 | B17: =Cleaned_Prepared_Data!B17 -> 45658 | C17: =Cleaned_Prepared_Data!C17 -> East | D17: =Cleaned_Prepared_Data!D17 -> Residential | E17: =Cleaned_Prepared_Data!M17 -> 922168.6 | F17: =Multiple_Regression!$B$6+Multiple_Regression!$B$7*Cleaned_Prepared_Data!F17+Multiple_Regression!$B$8*Cleaned_Prepared_Data!E17+Multiple_Regression!$B$9*Cleaned_Prepared_Data!I17+Multiple_Regression!$B$10*Cleaned_Prepared_Data!H17+Multiple_Regression!$B$11*Cleaned_Prepared_Data!G17+Multiple_Regression!$B$12*Dummy_Variables!D17+Multiple_Regression!$B$13*Dummy_Variables!E17+Multiple_Regression!$B$14*Dummy_Variables!F17 -> 880917.6 | G17: =E17-F17 -> 41251 | J17: =INDEX($A$5:$A$310,MATCH(SMALL($G$5:$G$310,4),$G$5:$G$310,0)) -> STR-1001 | K17: =INDEX($D$5:$D$310,MATCH(SMALL($G$5:$G$310,4),$G$5:$G$310,0)) -> Residential | L17: =SMALL($G$5:$G$310,4) -> -103034.74 | M17: =INDEX($F$5:$F$310,MATCH(SMALL($G$5:$G$310,4),$G$5:$G$310,0)) -> 761955.04
A18: =Cleaned_Prepared_Data!A18 -> STR-1004 | B18: =Cleaned_Prepared_Data!B18 -> 45689 | C18: =Cleaned_Prepared_Data!C18 -> East | D18: =Cleaned_Prepared_Data!D18 -> Residential | E18: =Cleaned_Prepared_Data!M18 -> 726606.28 | F18: =Multiple_Regression!$B$6+Multiple_Regression!$B$7*Cleaned_Prepared_Data!F18+Multiple_Regression!$B$8*Cleaned_Prepared_Data!E18+Multiple_Regression!$B$9*Cleaned_Prepared_Data!I18+Multiple_Regression!$B$10*Cleaned_Prepared_Data!H18+Multiple_Regression!$B$11*Cleaned_Prepared_Data!G18+Multiple_Regression!$B$12*Dummy_Variables!D18+Multiple_Regression!$B$13*Dummy_Variables!E18+Multiple_Regression!$B$14*Dummy_Variables!F18 -> 775326.61 | G18: =E18-F18 -> -48720.335 | J18: =INDEX($A$5:$A$310,MATCH(SMALL($G$5:$G$310,5),$G$5:$G$310,0)) -> STR-1007 | K18: =INDEX($D$5:$D$310,MATCH(SMALL($G$5:$G$310,5),$G$5:$G$310,0)) -> Mall | L18: =SMALL($G$5:$G$310,5) -> -101680.26 | M18: =INDEX($F$5:$F$310,MATCH(SMALL($G$5:$G$310,5),$G$5:$G$310,0)) -> 902132.2
A19: =Cleaned_Prepared_Data!A19 -> STR-1004 | B19: =Cleaned_Prepared_Data!B19 -> 45717 | C19: =Cleaned_Prepared_Data!C19 -> East | D19: =Cleaned_Prepared_Data!D19 -> Residential | E19: =Cleaned_Prepared_Data!M19 -> 746501.09 | F19: =Multiple_Regression!$B$6+Multiple_Regression!$B$7*Cleaned_Prepared_Data!F19+Multiple_Regression!$B$8*Cleaned_Prepared_Data!E19+Multiple_Regression!$B$9*Cleaned_Prepared_Data!I19+Multiple_Regression!$B$10*Cleaned_Prepared_Data!H19+Multiple_Regression!$B$11*Cleaned_Prepared_Data!G19+Multiple_Regression!$B$12*Dummy_Variables!D19+Multiple_Regression!$B$13*Dummy_Variables!E19+Multiple_Regression!$B$14*Dummy_Variables!F19 -> 750505.8 | G19: =E19-F19 -> -4004.7076
A20: =Cleaned_Prepared_Data!A20 -> STR-1004 | B20: =Cleaned_Prepared_Data!B20 -> 45748 | C20: =Cleaned_Prepared_Data!C20 -> East | D20: =Cleaned_Prepared_Data!D20 -> Residential | E20: =Cleaned_Prepared_Data!M20 -> 834017.02 | F20: =Multiple_Regression!$B$6+Multiple_Regression!$B$7*Cleaned_Prepared_Data!F20+Multiple_Regression!$B$8*Cleaned_Prepared_Data!E20+Multiple_Regression!$B$9*Cleaned_Prepared_Data!I20+Multiple_Regression!$B$10*Cleaned_Prepared_Data!H20+Multiple_Regression!$B$11*Cleaned_Prepared_Data!G20+Multiple_Regression!$B$12*Dummy_Variables!D20+Multiple_Regression!$B$13*Dummy_Variables!E20+Multiple_Regression!$B$14*Dummy_Variables!F20 -> 812808.05 | G20: =E20-F20 -> 21208.966 | J20: Residual diagnostics:
A21: =Cleaned_Prepared_Data!A21 -> STR-1005 | B21: =Cleaned_Prepared_Data!B21 -> 45658 | C21: =Cleaned_Prepared_Data!C21 -> South | D21: =Cleaned_Prepared_Data!D21 -> Residential | E21: =Cleaned_Prepared_Data!M21 -> 666152.52 | F21: =Multiple_Regression!$B$6+Multiple_Regression!$B$7*Cleaned_Prepared_Data!F21+Multiple_Regression!$B$8*Cleaned_Prepared_Data!E21+Multiple_Regression!$B$9*Cleaned_Prepared_Data!I21+Multiple_Regression!$B$10*Cleaned_Prepared_Data!H21+Multiple_Regression!$B$11*Cleaned_Prepared_Data!G21+Multiple_Regression!$B$12*Dummy_Variables!D21+Multiple_Regression!$B$13*Dummy_Variables!E21+Multiple_Regression!$B$14*Dummy_Variables!F21 -> 673002.27 | G21: =E21-F21 -> -6849.7506 | J21: Mean residual: | K21: =AVERAGE(G5:G310) -> -2.6250514e-11
A22: =Cleaned_Prepared_Data!A22 -> STR-1005 | B22: =Cleaned_Prepared_Data!B22 -> 45689 | C22: =Cleaned_Prepared_Data!C22 -> South | D22: =Cleaned_Prepared_Data!D22 -> Residential | E22: =Cleaned_Prepared_Data!M22 -> 573155.19 | F22: =Multiple_Regression!$B$6+Multiple_Regression!$B$7*Cleaned_Prepared_Data!F22+Multiple_Regression!$B$8*Cleaned_Prepared_Data!E22+Multiple_Regression!$B$9*Cleaned_Prepared_Data!I22+Multiple_Regression!$B$10*Cleaned_Prepared_Data!H22+Multiple_Regression!$B$11*Cleaned_Prepared_Data!G22+Multiple_Regression!$B$12*Dummy_Variables!D22+Multiple_Regression!$B$13*Dummy_Variables!E22+Multiple_Regression!$B$14*Dummy_Variables!F22 -> 581417.43 | G22: =E22-F22 -> -8262.2354 | J22: Std dev of residuals: | K22: =STDEV(G5:G310) -> 43847.309
A23: =Cleaned_Prepared_Data!A23 -> STR-1005 | B23: =Cleaned_Prepared_Data!B23 -> 45717 | C23: =Cleaned_Prepared_Data!C23 -> South | D23: =Cleaned_Prepared_Data!D23 -> Residential | E23: =Cleaned_Prepared_Data!M23 -> 666573.2 | F23: =Multiple_Regression!$B$6+Multiple_Regression!$B$7*Cleaned_Prepared_Data!F23+Multiple_Regression!$B$8*Cleaned_Prepared_Data!E23+Multiple_Regression!$B$9*Cleaned_Prepared_Data!I23+Multiple_Regression!$B$10*Cleaned_Prepared_Data!H23+Multiple_Regression!$B$11*Cleaned_Prepared_Data!G23+Multiple_Regression!$B$12*Dummy_Variables!D23+Multiple_Regression!$B$13*Dummy_Variables!E23+Multiple_Regression!$B$14*Dummy_Variables!F23 -> 682367.27 | G23: =E23-F23 -> -15794.069 | J23: Max positive residual: | K23: =MAX(G5:G310) -> 105973.74
A24: =Cleaned_Prepared_Data!A24 -> STR-1005 | B24: =Cleaned_Prepared_Data!B24 -> 45748 | C24: =Cleaned_Prepared_Data!C24 -> South | D24: =Cleaned_Prepared_Data!D24 -> Residential | E24: =Cleaned_Prepared_Data!M24 -> 591619.95 | F24: =Multiple_Regression!$B$6+Multiple_Regression!$B$7*Cleaned_Prepared_Data!F24+Multiple_Regression!$B$8*Cleaned_Prepared_Data!E24+Multiple_Regression!$B$9*Cleaned_Prepared_Data!I24+Multiple_Regression!$B$10*Cleaned_Prepared_Data!H24+Multiple_Regression!$B$11*Cleaned_Prepared_Data!G24+Multiple_Regression!$B$12*Dummy_Variables!D24+Multiple_Regression!$B$13*Dummy_Variables!E24+Multiple_Regression!$B$14*Dummy_Variables!F24 -> 597027.51 | G24: =E24-F24 -> -5407.5588 | J24: Max negative residual: | K24: =MIN(G5:G310) -> -152088.74
A25: =Cleaned_Prepared_Data!A25 -> STR-1006 | B25: =Cleaned_Prepared_Data!B25 -> 45658 | C25: =Cleaned_Prepared_Data!C25 -> North | D25: =Cleaned_Prepared_Data!D25 -> Residential | E25: =Cleaned_Prepared_Data!M25 -> 415721.82 | F25: =Multiple_Regression!$B$6+Multiple_Regression!$B$7*Cleaned_Prepared_Data!F25+Multiple_Regression!$B$8*Cleaned_Prepared_Data!E25+Multiple_Regression!$B$9*Cleaned_Prepared_Data!I25+Multiple_Regression!$B$10*Cleaned_Prepared_Data!H25+Multiple_Regression!$B$11*Cleaned_Prepared_Data!G25+Multiple_Regression!$B$12*Dummy_Variables!D25+Multiple_Regression!$B$13*Dummy_Variables!E25+Multiple_Regression!$B$14*Dummy_Variables!F25 -> 492417.99 | G25: =E25-F25 -> -76696.171
A26: =Cleaned_Prepared_Data!A26 -> STR-1006 | B26: =Cleaned_Prepared_Data!B26 -> 45689 | C26: =Cleaned_Prepared_Data!C26 -> North | D26: =Cleaned_Prepared_Data!D26 -> Residential | E26: =Cleaned_Prepared_Data!M26 -> 491905.13 | F26: =Multiple_Regression!$B$6+Multiple_Regression!$B$7*Cleaned_Prepared_Data!F26+Multiple_Regression!$B$8*Cleaned_Prepared_Data!E26+Multiple_Regression!$B$9*Cleaned_Prepared_Data!I26+Multiple_Regression!$B$10*Cleaned_Prepared_Data!H26+Multiple_Regression!$B$11*Cleaned_Prepared_Data!G26+Multiple_Regression!$B$12*Dummy_Variables!D26+Multiple_Regression!$B$13*Dummy_Variables!E26+Multiple_Regression!$B$14*Dummy_Variables!F26 -> 486923.21 | G26: =E26-F26 -> 4981.9152
A27: =Cleaned_Prepared_Data!A27 -> STR-1006 | B27: =Cleaned_Prepared_Data!B27 -> 45717 | C27: =Cleaned_Prepared_Data!C27 -> North | D27: =Cleaned_Prepared_Data!D27 -> Residential | E27: =Cleaned_Prepared_Data!M27 -> 555929.4 | F27: =Multiple_Regression!$B$6+Multiple_Regression!$B$7*Cleaned_Prepared_Data!F27+Multiple_Regression!$B$8*Cleaned_Prepared_Data!E27+Multiple_Regression!$B$9*Cleaned_Prepared_Data!I27+Multiple_Regression!$B$10*Cleaned_Prepared_Data!H27+Multiple_Regression!$B$11*Cleaned_Prepared_Data!G27+Multiple_Regression!$B$12*Dummy_Variables!D27+Multiple_Regression!$B$13*Dummy_Variables!E27+Multiple_Regression!$B$14*Dummy_Variables!F27 -> 528577.32 | G27: =E27-F27 -> 27352.084
A28: =Cleaned_Prepared_Data!A28 -> STR-1006 | B28: =Cleaned_Prepared_Data!B28 -> 45748 | C28: =Cleaned_Prepared_Data!C28 -> North | D28: =Cleaned_Prepared_Data!D28 -> Residential | E28: =Cleaned_Prepared_Data!M28 -> 565810.99 | F28: =Multiple_Regression!$B$6+Multiple_Regression!$B$7*Cleaned_Prepared_Data!F28+Multiple_Regression!$B$8*Cleaned_Prepared_Data!E28+Multiple_Regression!$B$9*Cleaned_Prepared_Data!I28+Multiple_Regression!$B$10*Cleaned_Prepared_Data!H28+Multiple_Regression!$B$11*Cleaned_Prepared_Data!G28+Multiple_Regression!$B$12*Dummy_Variables!D28+Multiple_Regression!$B$13*Dummy_Variables!E28+Multiple_Regression!$B$14*Dummy_Variables!F28 -> 552646.23 | G28: =E28-F28 -> 13164.756
A29: =Cleaned_Prepared_Data!A29 -> STR-1007 | B29: =Cleaned_Prepared_Data!B29 -> 45658 | C29: =Cleaned_Prepared_Data!C29 -> West | D29: =Cleaned_Prepared_Data!D29 -> Mall | E29: =Cleaned_Prepared_Data!M29 -> 811771.14 | F29: =Multiple_Regression!$B$6+Multiple_Regression!$B$7*Cleaned_Prepared_Data!F29+Multiple_Regression!$B$8*Cleaned_Prepared_Data!E29+Multiple_Regression!$B$9*Cleaned_Prepared_Data!I29+Multiple_Regression!$B$10*Cleaned_Prepared_Data!H29+Multiple_Regression!$B$11*Cleaned_Prepared_Data!G29+Multiple_Regression!$B$12*Dummy_Variables!D29+Multiple_Regression!$B$13*Dummy_Variables!E29+Multiple_Regression!$B$14*Dummy_Variables!F29 -> 841159.51 | G29: =E29-F29 -> -29388.367
A30: =Cleaned_Prepared_Data!A30 -> STR-1007 | B30: =Cleaned_Prepared_Data!B30 -> 45689 | C30: =Cleaned_Prepared_Data!C30 -> West | D30: =Cleaned_Prepared_Data!D30 -> Mall | E30: =Cleaned_Prepared_Data!M30 -> 800451.94 | F30: =Multiple_Regression!$B$6+Multiple_Regression!$B$7*Cleaned_Prepared_Data!F30+Multiple_Regression!$B$8*Cleaned_Prepared_Data!E30+Multiple_Regression!$B$9*Cleaned_Prepared_Data!I30+Multiple_Regression!$B$10*Cleaned_Prepared_Data!H30+Multiple_Regression!$B$11*Cleaned_Prepared_Data!G30+Multiple_Regression!$B$12*Dummy_Variables!D30+Multiple_Regression!$B$13*Dummy_Variables!E30+Multiple_Regression!$B$14*Dummy_Variables!F30 -> 902132.2 | G30: =E30-F30 -> -101680.26
A31: =Cleaned_Prepared_Data!A31 -> STR-1007 | B31: =Cleaned_Prepared_Data!B31 -> 45717 | C31: =Cleaned_Prepared_Data!C31 -> West | D31: =Cleaned_Prepared_Data!D31 -> Mall | E31: =Cleaned_Prepared_Data!M31 -> 783672.82 | F31: =Multiple_Regression!$B$6+Multiple_Regression!$B$7*Cleaned_Prepared_Data!F31+Multiple_Regression!$B$8*Cleaned_Prepared_Data!E31+Multiple_Regression!$B$9*Cleaned_Prepared_Data!I31+Multiple_Regression!$B$10*Cleaned_Prepared_Data!H31+Multiple_Regression!$B$11*Cleaned_Prepared_Data!G31+Multiple_Regression!$B$12*Dummy_Variables!D31+Multiple_Regression!$B$13*Dummy_Variables!E31+Multiple_Regression!$B$14*Dummy_Variables!F31 -> 795939.47 | G31: =E31-F31 -> -12266.651
A32: =Cleaned_Prepared_Data!A32 -> STR-1007 | B32: =Cleaned_Prepared_Data!B32 -> 45748 | C32: =Cleaned_Prepared_Data!C32 -> West | D32: =Cleaned_Prepared_Data!D32 -> Mall | E32: =Cleaned_Prepared_Data!M32 -> 701641.97 | F32: =Multiple_Regression!$B$6+Multiple_Regression!$B$7*Cleaned_Prepared_Data!F32+Multiple_Regression!$B$8*Cleaned_Prepared_Data!E32+Multiple_Regression!$B$9*Cleaned_Prepared_Data!I32+Multiple_Regression!$B$10*Cleaned_Prepared_Data!H32+Multiple_Regression!$B$11*Cleaned_Prepared_Data!G32+Multiple_Regression!$B$12*Dummy_Variables!D32+Multiple_Regression!$B$13*Dummy_Variables!E32+Multiple_Regression!$B$14*Dummy_Variables!F32 -> 694644.48 | G32: =E32-F32 -> 6997.4936
A33: =Cleaned_Prepared_Data!A33 -> STR-1008 | B33: =Cleaned_Prepared_Data!B33 -> 45658 | C33: =Cleaned_Prepared_Data!C33 -> East | D33: =Cleaned_Prepared_Data!D33 -> Residential | E33: =Cleaned_Prepared_Data!M33 -> 511844.41 | F33: =Multiple_Regression!$B$6+Multiple_Regression!$B$7*Cleaned_Prepared_Data!F33+Multiple_Regression!$B$8*Cleaned_Prepared_Data!E33+Multiple_Regression!$B$9*Cleaned_Prepared_Data!I33+Multiple_Regression!$B$10*Cleaned_Prepared_Data!H33+Multiple_Regression!$B$11*Cleaned_Prepared_Data!G33+Multiple_Regression!$B$12*Dummy_Variables!D33+Multiple_Regression!$B$13*Dummy_Variables!E33+Multiple_Regression!$B$14*Dummy_Variables!F33 -> 582071.91 | G33: =E33-F33 -> -70227.496
A34: =Cleaned_Prepared_Data!A34 -> STR-1008 | B34: =Cleaned_Prepared_Data!B34 -> 45689 | C34: =Cleaned_Prepared_Data!C34 -> East | D34: =Cleaned_Prepared_Data!D34 -> Residential | E34: =Cleaned_Prepared_Data!M34 -> 537383.79 | F34: =Multiple_Regression!$B$6+Multiple_Regression!$B$7*Cleaned_Prepared_Data!F34+Multiple_Regression!$B$8*Cleaned_Prepared_Data!E34+Multiple_Regression!$B$9*Cleaned_Prepared_Data!I34+Multiple_Regression!$B$10*Cleaned_Prepared_Data!H34+Multiple_Regression!$B$11*Cleaned_Prepared_Data!G34+Multiple_Regression!$B$12*Dummy_Variables!D34+Multiple_Regression!$B$13*Dummy_Variables!E34+Multiple_Regression!$B$14*Dummy_Variables!F34 -> 526290.38 | G34: =E34-F34 -> 11093.411
A35: =Cleaned_Prepared_Data!A35 -> STR-1008 | B35: =Cleaned_Prepared_Data!B35 -> 45717 | C35: =Cleaned_Prepared_Data!C35 -> East | D35: =Cleaned_Prepared_Data!D35 -> Residential | E35: =Cleaned_Prepared_Data!M35 -> 500173.02 | F35: =Multiple_Regression!$B$6+Multiple_Regression!$B$7*Cleaned_Prepared_Data!F35+Multiple_Regression!$B$8*Cleaned_Prepared_Data!E35+Multiple_Regression!$B$9*Cleaned_Prepared_Data!I35+Multiple_Regression!$B$10*Cleaned_Prepared_Data!H35+Multiple_Regression!$B$11*Cleaned_Prepared_Data!G35+Multiple_Regression!$B$12*Dummy_Variables!D35+Multiple_Regression!$B$13*Dummy_Variables!E35+Multiple_Regression!$B$14*Dummy_Variables!F35 -> 517975.22 | G35: =E35-F35 -> -17802.201
A36: =Cleaned_Prepared_Data!A36 -> STR-1008 | B36: =Cleaned_Prepared_Data!B36 -> 45748 | C36: =Cleaned_Prepared_Data!C36 -> East | D36: =Cleaned_Prepared_Data!D36 -> Residential | E36: =Cleaned_Prepared_Data!M36 -> 427917.38 | F36: =Multiple_Regression!$B$6+Multiple_Regression!$B$7*Cleaned_Prepared_Data!F36+Multiple_Regression!$B$8*Cleaned_Prepared_Data!E36+Multiple_Regression!$B$9*Cleaned_Prepared_Data!I36+Multiple_Regression!$B$10*Cleaned_Prepared_Data!H36+Multiple_Regression!$B$11*Cleaned_Prepared_Data!G36+Multiple_Regression!$B$12*Dummy_Variables!D36+Multiple_Regression!$B$13*Dummy_Variables!E36+Multiple_Regression!$B$14*Dummy_Variables!F36 -> 491928.83 | G36: =E36-F36 -> -64011.455
... A310: =Cleaned_Prepared_Data!A310 -> STR-1080 | B310: =Cleaned_Prepared_Data!B310 -> 45748 | C310: =Cleaned_Prepared_Data!C310 -> East | D310: =Cleaned_Prepared_Data!D310 -> Residential | E310: =Cleaned_Prepared_Data!M310 -> 559660.84 | F310: =Multiple_Regression!$B$6+Multiple_Regression!$B$7*Cleaned_Prepared_Data!F310+Multiple_Regression!$B$8*Cleaned_Prepared_Data!E310+Multiple_Regression!$B$9*Cleaned_Prepared_Data!I310+Multiple_Regression!$B$10*Cleaned_Prepared_Data!H310+Multiple_Regression!$B$11*Cleaned_Prepared_Data!G310+Multiple_Regression!$B$12*Dummy_Variables!D310+Multiple_Regression!$B$13*Dummy_Variables!E310+Multiple_Regression!$B$14*Dummy_Variables!F310 -> 599878.59 | G310: =E310-F310 -> -40217.749

Sheet Model_Comparison
A1: Model Comparison Summary
A3: Model | B3: Type | C3: Independent Variable(s) | D3: R-squared | E3: Key P-value(s) | F3: Significant? | G3: Business Usefulness
A4: SR1 | B4: Simple | C4: marketing_spend | D4: =Simple_Regression!B6 -> 0.15742646 | E4: =Simple_Regression!B10 -> 5.5808923e-13 | F4: =IF(E4<0.05,"Yes (p<0.05)","No") -> Yes (p<0.05) | G4: Weak standalone predictor — explains only ~16% of sales variation. Useful directionally but not for forecasting alone.
A5: SR2 | B5: Simple | C5: footfall | D5: =Simple_Regression!B17 -> 0.73484317 | E5: =Simple_Regression!B21 -> 1.2559351e-89 | F5: =IF(E5<0.05,"Yes (p<0.05)","No") -> Yes (p<0.05) | G5: Strongest single-variable predictor — footfall alone explains ~73% of sales variation. Good leading indicator.
A6: SR3 | B6: Simple | C6: avg_discount_pct | D6: =Simple_Regression!B28 -> 0.0057430355 | E6: =Simple_Regression!B32 -> 0.1861234 | F6: =IF(E6<0.05,"Yes (p<0.05)","No") -> No | G6: Not statistically significant on its own (p>0.05). Discounting alone does not reliably explain sales differences.
A7: MR1 (Final Model) | B7: Multiple | C7: footfall, marketing_spend, inventory_availability_pct, staff_count, avg_discount_pct, store_type (dummies) | D7: =Multiple_Regression!B16 -> 0.8185268 | E7: =Multiple_Regression!B7 & ", " & Multiple_Regression!B8 & ", " & Multiple_Regression!B9 -> 28.7855980517642, 1.14957266896365, 2856.87163294988 | F7: Mostly Yes (see notes) | G7: Best overall model — explains ~82% of sales variation. Combines operational levers (footfall, marketing, inventory, staffing) with store-format effects. Most useful for business decisions.
A9: R-squared comparison (higher = more variation explained):
A10: SR1 (marketing_spend): | B10: =Simple_Regression!B6 -> 0.15742646
A11: SR2 (footfall): | B11: =Simple_Regression!B17 -> 0.73484317
A12: SR3 (avg_discount_pct): | B12: =Simple_Regression!B28 -> 0.0057430355
A13: MR1 (Multiple Regression, final): | B13: =Multiple_Regression!B16 -> 0.8185268
A15: Conclusion: MR1 selected as final model — highest R-squared, includes operational variables leadership can act on, and isolates store-format (dummy) effects.
